Workbook
Name _: #REF!
Name _____________x1: #REF!
Name _____________x2: #REF!
Name ____________x1: #REF!
Name ____________x2: #REF!
Name ___________x1: #REF!
Name ___________x2: #REF!
Name __________x1: #REF!
Name __________x2: #REF!
Name _________x1: #REF!
Name _________x2: #REF!
Name ________x1: #REF!
Name ________x2: #REF!
Name _______x1: #REF!
Name _______x2: #REF!
Name ______x1: #REF!
Name ______x2: #REF!
Name _____x1: #REF!
Name _____x2: #REF!
Name ____1STYR: #REF!
Name ____bnd2: #REF!
Name ____cod1: #REF!
Name ____cod10: #REF!
Name ____cod2: #REF!
Name ____cod3: #REF!
Name ____cod4: #REF!
Name ____cod5: #REF!
Name ____cod6: #REF!
Name ____cod7: #REF!
Name ____cod8: #REF!
Name ____cod9: #REF!
Name ____let1: #REF!
Name ____ord1: #REF!
Name ____ord2: #REF!
Name ____ord3: #REF!
Name ____rrc1: #REF!
Name ____rrc2: #REF!
Name ____sc1: #REF!
Name ____su1: #REF!
Name ____su2: #REF!
Name ____tdp1: #REF!
Name ____TOP2: #REF!
Name ____TOP3: #REF!
Name ____TOP4: #REF!
Name ____TOP5: #REF!
Name ____TOP6: #REF!
Name ____TOP7: #REF!
Name ____ubr1: #REF!
Name ____vat1: #REF!
Name ____x1: #REF!
Name ____x2: #REF!
Name ___10__123Graph_BCHART_4: #REF!
Name ___11__123Graph_BCHART_5: #REF!
Name ___12__123Graph_BCHART_6: #REF!
Name ___13__123Graph_BCHART_7: #REF!
Name ___14__123Graph_CCHART_4: #REF!
Name ___17__123Graph_XCHART_5: #REF!
Name ___18__123Graph_XCHART_6: #REF!
Name ___19__123Graph_XCHART_7: #REF!
Name ___1STYR: #REF!

Sheet Rédaction BAIL
A1: Article | B1: Désignation | C1: Nom Source | D1: Source | E1: Donnée source | F1: Condition | G1: Entrée correspondante - Option 1 | H1: Commentaire | I1: Condition Option 2 | J1: Entrée correspondante - Option 2 | K1: Commentaire
A2: Comparution | B2: Comparution Bailleur | C2: Société Bailleur | D2: ='1. Données historiques'!B4 | E2: SCI FORGEOT PROPERTY | G2: La Société FORGEOT PROPERTY, société civile Immobilière au capital de 310.000 €, dont le siège social est à PARIS (75017), 267 boulevard Pereire, immatriculée au Registre du Commerce et des Sociétés de PARIS sous le numéro unique d'identification 804 088 094, Représentée par son gérant, la Société F&A ASSET MANAGEMENT, SAS dont le siège social est à Paris (75017) - 267, Boulevard Pereire, immatriculée au Registre du Commerce et des Sociétés de Paris sous le numéro B 824 057 087, Elle-même représentée par son Président Monsieur Maxime FORGEOT, dument habilité à l'effet des présentes. Ci-après dénommée : le « Bailleur »
C3: Société Bailleur | D3: ='1. Données historiques'!B4 | E3: SCI FORGEOT RETAIL | G3: La Société FORGEOT RETAIL, société civile Immobilière au capital de 10.000 €, dont le siège social est à PARIS (75017), 267 boulevard Pereire, immatriculée au Registre du Commerce et des Sociétés de PARIS sous le numéro unique d'identification 804 048 445, Représentée par son gérant, la Société F&A ASSET MANAGEMENT, SAS dont le siège social est à Paris (75017) - 267, Boulevard Pereire, immatriculée au Registre du Commerce et des Sociétés de Paris sous le numéro B 824 057 087, Elle-même représentée par son Président Monsieur Maxime FORGEOT, dument habilité à l'effet des présentes. Ci-après dénommée : le « Bailleur »
C4: Société Bailleur | D4: ='1. Données historiques'!B4 | E4: SCI HSR 1 | G4: La Société HIGH STREET RETAIL 1, société civile Immobilière au capital de 10.000 €, dont le siège social est à PARIS (75017), 267 boulevard Pereire, immatriculée au Registre du Commerce et des Sociétés de PARIS sous le numéro unique d'identification 825 190 317, Représentée par son gérant, la Société F&A ASSET MANAGEMENT, SAS dont le siège social est à Paris (75017) - 267, Boulevard Pereire, immatriculée au Registre du Commerce et des Sociétés de Paris sous le numéro B 824 057 087, Elle-même représentée par son Président Monsieur Maxime FORGEOT, dument habilité à l'effet des présentes. Ci-après dénommée : le « Bailleur »
C5: Société Bailleur | D5: ='1. Données historiques'!B4 | E5: SCI HSR 2 | G5: La Société HIGH STREET RETAIL 2, société civile Immobilière au capital de 10.000 €, dont le siège social est à PARIS (75017), 267 boulevard Pereire, immatriculée au Registre du Commerce et des Sociétés de PARIS sous le numéro unique d'identification 830 917 134, Représentée par son gérant, la Société F&A ASSET MANAGEMENT, SAS dont le siège social est à Paris (75017) - 267, Boulevard Pereire, immatriculée au Registre du Commerce et des Sociétés de Paris sous le numéro B 824 057 087, Elle-même représentée par son Président Monsieur Maxime FORGEOT, dument habilité à l'effet des présentes. Ci-après dénommée : le « Bailleur »
C6: Société Bailleur | D6: ='1. Données historiques'!B4 | E6: SARL HSR 3 | G6: La Société HIGH STREET RETAIL 3, société à responsabilité limitée au capital de 1.000 €, dont le siège social est à PARIS (75017), 267 boulevard Pereire, immatriculée au Registre du Commerce et des Sociétés de PARIS sous le numéro unique d'identification 810 334 102, Représentée par son gérant, la Société F&A ASSET MANAGEMENT, SAS dont le siège social est à Paris (75017) - 267, Boulevard Pereire, immatriculée au Registre du Commerce et des Sociétés de Paris sous le numéro B 824 057 087, Elle-même représentée par son Président Monsieur Maxime FORGEOT, dument habilité à l'effet des présentes. Ci-après dénommée : le « Bailleur »
C7: Société Bailleur | D7: ='1. Données historiques'!B4 | E7: SAS HSR 4 | G7: La Société HIGH STREET RETAIL 4, société par actions simplifiée au capital de 72.000 €, dont le siège social est à PARIS (75017), 267 boulevard Pereire, immatriculée au Registre du Commerce et des Sociétés de PARIS sous le numéro unique d'identification 390 174 589, Représentée par son gérant, la Société F&A ASSET MANAGEMENT, SAS dont le siège social est à Paris (75017) - 267, Boulevard Pereire, immatriculée au Registre du Commerce et des Sociétés de Paris sous le numéro B 824 057 087, Elle-même représentée par son Président Monsieur Maxime FORGEOT, dument habilité à l'effet des présentes. Ci-après dénommée : le « Bailleur »
C8: Société Bailleur | D8: ='1. Données historiques'!B4 | E8: SCI HSR 5 | G8: La Société HIGH STREET RETAIL 5, société civile Immobilière au capital de 10.000 €, dont le siège social est à PARIS (75017), 267 boulevard Pereire, immatriculée au Registre du Commerce et des Sociétés de PARIS sous le numéro unique d'identification 850 407 149, Représentée par son gérant, la Société F&A ASSET MANAGEMENT, SAS dont le siège social est à Paris (75017) - 267, Boulevard Pereire, immatriculée au Registre du Commerce et des Sociétés de Paris sous le numéro B 824 057 087, Elle-même représentée par son Président Monsieur Maxime FORGEOT, dument habilité à l'effet des présentes. Ci-après dénommée : le « Bailleur »
C9: Société Bailleur | D9: ='1. Données historiques'!B4 | E9: SCI HSR 6 | G9: La Société HIGH STREET RETAIL 6, société civile Immobilière au capital de 10.000 €, dont le siège social est à PARIS (75017), 267 boulevard Pereire, immatriculée au Registre du Commerce et des Sociétés de PARIS sous le numéro unique d'identification 914 859 434, Représentée par son gérant, la Société F&A ASSET MANAGEMENT, SAS dont le siège social est à Paris (75017) - 267, Boulevard Pereire, immatriculée au Registre du Commerce et des Sociétés de Paris sous le numéro B 824 057 087, Elle-même représentée par son Président Monsieur Maxime FORGEOT, dument habilité à l'effet des présentes. Ci-après dénommée : le « Bailleur »
C10: Société Bailleur | D10: ='1. Données historiques'!B4 | E10: SCI RETAIL RENNES 1 | G10: La Société HRETAIL RENNES 1, société civile Immobilière au capital de 11.098 €, dont le siège social est à PARIS (75017), 267 boulevard Pereire, immatriculée au Registre du Commerce et des Sociétés de PARIS sous le numéro unique d'identification 801 971 508, Représentée par son gérant, la Société F&A ASSET MANAGEMENT, SAS dont le siège social est à Paris (75017) - 267, Boulevard Pereire, immatriculée au Registre du Commerce et des Sociétés de Paris sous le numéro B 824 057 087, Elle-même représentée par son Président Monsieur Maxime FORGEOT, dument habilité à l'effet des présentes. Ci-après dénommée : le « Bailleur »
C11: Société Bailleur | D11: ='1. Données historiques'!B4 | E11: SCI RETAIL RENNES 2 | G11: La Société RETAIL RENNES 2, société civile Immobilière au capital de 39.748 €, dont le siège social est à PARIS (75017), 267 boulevard Pereire, immatriculée au Registre du Commerce et des Sociétés de PARIS sous le numéro unique d'identification 801 932 617, Représentée par son gérant, la Société F&A ASSET MANAGEMENT, SAS dont le siège social est à Paris (75017) - 267, Boulevard Pereire, immatriculée au Registre du Commerce et des Sociétés de Paris sous le numéro B 824 057 087, Elle-même représentée par son Président Monsieur Maxime FORGEOT, dument habilité à l'effet des présentes. Ci-après dénommée : le « Bailleur »
A12: Comparution | B12: Comparution Preneur | C12: Type Preneur Nom Preneur Siret Preneur | D12: =Validation!B24 | E12: =Liste!I19 -> Personne Physique | G12: Monsieur/Madame [Nom Preneur], né le [.] à [.], [profession], demeurant [.], marié avec Madame |PRÉNOMS + NOM de JEUNE FILLE] née le [.] à [.] sous le régime de la séparation de biens suivant contrat de mariage reçu par Me [NOM DU NOTAIRE] à [.] ayant précédé leur union célébrée le [DATE DU MARIAGE] en la Commune de [.]. Si personne marié sous le régime de la communauté : Monsieur [PRENOMS + NOM], né le [.] à [.], [profession], Et Madame |PRÉNOMS + NOM de JEUNE FILLE] née le [.] à [.], [profession], Demeurant ensemble [.], Mariés sous le régime de la communauté légale suivant mariage célébré le [DATE DU MARIAGE] en la Commune de [.]. Si personne pacsée : Monsieur [PRENOMS + NOM], né le [.] à [.], [profession], demeurant [.], pacsé avec Madame |PRÉNOMS + NOM de JEUNE FILLE] née le [.] à [.] sous le régime de la séparation.
C13: Type Preneur Nom Preneur Siret Preneur | D13: =Validation!B24 | E13: SAS | G13: La société [NOM DE LA SOCIETE], Société [TYPE DE SOCIETE] au capital de [CAPITAL SOCIAL], immatriculée au Registre du Commerce et des Sociétés de [LOCALITE RCS] sous le numéro [N° DE SIRET], dont le siège social est à [ADRESSE DE DOMICILIATION], représentée par Madame/Monsieur [PRESIDENT DE LA SOCIETE], dûment habilité aux fins des présentes en vertu [.], ci-après annexé
C14: Type Preneur Nom Preneur Siret Preneur | D14: =Validation!B24 | E14: SARL | G14: La société [NOM DE LA SOCIETE], Société [TYPE DE SOCIETE] au capital de [CAPITAL SOCIAL], immatriculée au Registre du Commerce et des Sociétés de [LOCALITE RCS] sous le numéro [N° DE SIRET], dont le siège social est à [ADRESSE DE DOMICILIATION], représentée par Madame/Monsieur [PRESIDENT DE LA SOCIETE], dûment habilité aux fins des présentes en vertu [.], ci-après annexé
C15: Type Preneur Nom Preneur Siret Preneur | D15: =Validation!B24 | E15: EURL | G15: La société [NOM DE LA SOCIETE], Société [TYPE DE SOCIETE] au capital de [CAPITAL SOCIAL], immatriculée au Registre du Commerce et des Sociétés de [LOCALITE RCS] sous le numéro [N° DE SIRET], dont le siège social est à [ADRESSE DE DOMICILIATION], représentée par Madame/Monsieur [PRESIDENT DE LA SOCIETE], dûment habilité aux fins des présentes en vertu [.], ci-après annexé
C16: Type Preneur Nom Preneur Siret Preneur | D16: =Validation!B24 | E16: Société en formation | G16: PRÉVOIR si le preneur agit pour le compte d’une société en formation : La société XXXX, société [.] au capital de [.], en cours d’immatriculation auprès du Registre du Commerce et des Sociétés de [.], dont le siège social est à [.], représentée par Madame/Monsieur [.], dûment habilité aux fins des présentes en vertu, Ou si personne physique : Si personne marié sous le régime de la séparation : Monsieur [PRENOMS + NOM], né le [.] à [.], [profession], demeurant [.], marié avec Madame |PRÉNOMS + NOM de JEUNE FILLE] née le [.] à [.] sous le régime de la séparation de biens suivant contrat de mariage reçu par Me [NOM DU NOTAIRE] à [.] ayant précédé leur union célébrée le [DATE DU MARIAGE] en la Commune de [.]. Si personne marié sous le régime de la communauté : Monsieur [PRENOMS + NOM], né le [.] à [.], [profession], Et Madame |PRÉNOMS + NOM de JEUNE FILLE] née le [.] à [.], [profession], Demeurant ensemble [.], Mariés sous le régime de la communauté légale suivant mariage célébré le [DATE DU MARIAGE] en la Commune de [.]. Si personne pacsée : Monsieur [PRENOMS + NOM], né le [.] à [.], [profession], demeurant [.], pacsé avec Madame |PRÉNOMS + NOM de JEUNE FILLE] née le [.] à [.] sous le régime de la séparation. [Idem pour tous les associés de la société en cours de formation] Agissant au nom et pour le compte de la société [●], société [●] au capital de [●] euros dont le siège est situé [●], en cours de formation auprès du Registre du Commerce et des Sociétés de [●]. Il est expressément rappelé que le présent acte est passé et réalisé pour le compte de la société XXXXXXXXXX, société en cours de formation conformément à l’article L.210-6 du Code de Commerce et dans le cadre des dispositions de l'article 1843 du Code civil et du 3e paragraphe de l'article 6 du décret n° 78-704 du 3 juillet 1978. Il est rappelé que, conformément aux dispositions des textes précités, l'immatriculation de la société dont s'agit au Registre du commerce et des sociétés emportera reprise à son profit de ladite opération, qui sera alors réputée avoir été effectuée dès l'origine par la société elle-même. Afin de fixer un terme à la période d'incertitude quant à la personne du Preneur définitif, résultant des dispositions ci-dessus rappelées, si l'immatriculation de la société n'intervient pas dans un délai de DEUX MOIS à compter du présent acte, le présent Bail se trouvera conclu de façon définitive par tous les associés de ladite société, et ce, dans les mêmes proportions que celles de leurs droits dans le capital social. À ce titre, il est précisé que les associés fondateurs sont : - XXXXXXX
A17: Article préliminaire | B17: Conditions suspensives et délais | C17: Conditions suspensives 1, 2, 3, 4. | D17: ='3. Hypothèses'!E38:E41 | E17: =Liste!K19 -> Financement | G17: ARTICLE PRELIMINAIRE : BAIL SOUS CONDITION SUSPENSIVE 1. Condition suspensive et délais Le présent Bail est consenti et accepté par le Bailleur et le Preneur sous réserve de la réalisation de la condition suspensive suivante : - Obtention d’un prêt bancaire par le Preneur d’un montant de [X] € ([EN LETTRES] EUROS). Le Preneur devra justifier au Bailleur, au plus tard [X] ([EN LETTRES]) semaines suivant la signature des présentes, du dépôt d’une demande auprès d’au moins 2 (DEUX) établissement bancaires français, sous peine de caducité du présent Bail ; Ci-après la « Condition Suspensive » Chacune des Parties informera par tous moyens écrit l’autre partie de la réalisation de la condition suspensive qui lui incombe. En tout état de cause, la livraison des Locaux Loués au Preneur emportera levée de ladite condition suspensive sans autre formalité, chacune des Parties s’obligeant d’ores et déjà à respecter l’ensemble des clauses et conditions du présent Bail. Dans l'hypothèse où cette condition ne serait pas réalisée dans le délai indiqué ci-dessus, éventuellement prorogé, les obligations contractées par chacune des Parties au titre du présent Bail seront nulles et non avenues et les Parties reprendront, à ce titre, leur pleine et entière liberté sans indemnité de part et d’autre, les sommes versées par le Preneur lors de la signature du Bail lui seront remboursées. 2. Défaillance de la Condition Suspensive A défaut de réalisation de la Condition Suspensive dans le délai susvisé, les obligations contractées par chacune des Parties seront caduques, et les Parties reprendront leur pleine et entière liberté sans indemnité de part et d’autre, le Preneur ayant parfaitement connaissance de ce que le présent bail s’inscrit dans un contexte de libération desdits locaux laquelle n’est ni garantie et ni prévisible et ne pouvant, à ce titre, engager une quelconque action à l’encontre du Bailleur. Le Bailleur s’engageant à restituer au Preneur les sommes versées par le Preneur lors de la signature du Bail. | I17: Si plusieurs conditions suspensives | J17: ARTICLE PRELIMINAIRE : BAIL SOUS CONDITIONS SUSPENSIVES 1. Conditions suspensives et délais Le présent Bail est consenti et accepté par le Bailleur et le Preneur sous réserve de la réalisation des conditions suspensives suivantes : a. Obtention d’un prêt bancaire par le Preneur d’un montant de [X] € ([EN LETTRES] EUROS). Le Preneur devra justifier au Bailleur, au plus tard [X] ([EN LETTRES]) semaines suivant la signature des présentes, du dépôt d’une demande auprès d’au moins 2 (DEUX) établissement bancaires français, sous peine de caducité du présent Bail ; b. Ci-après les « Conditions Suspensives » Chacune des Parties informera par tous moyens écrit l’autre partie de la réalisation de la condition suspensive qui lui incombe. En tout état de cause, la livraison des Locaux Loués au Preneur emportera levée desdites conditions suspensives sans autre formalité, chacune des Parties s’obligeant d’ores et déjà à respecter l’ensemble des clauses et conditions du présent Bail. Dans l'hypothèse où ces conditions ne seraient pas réalisées dans le délai indiqué ci-dessus, éventuellement prorogé, les obligations contractées par chacune des Parties au titre du présent Bail seront nulles et non avenues et les Parties reprendront, à ce titre, leur pleine et entière liberté sans indemnité de part et d’autre, les sommes versées par le Preneur lors de la signature du Bail lui seront remboursées. 2. Défaillance des Conditions Suspensives A défaut de réalisation des Conditions Suspensives dans le délai susvisé, les obligations contractées par chacune des Parties seront caduques, et les Parties reprendront leur pleine et entière liberté sans indemnité de part et d’autre, le Preneur ayant parfaitement connaissance de ce que le présent bail s’inscrit dans un contexte de libération desdits locaux laquelle n’est ni garantie et ni prévisible et ne pouvant, à ce titre, engager une quelconque action à l’encontre du Bailleur. Le Bailleur s’engageant à restituer au Preneur les sommes versées par le Preneur lors de la signature du Bail. | K17: Si plusieurs conditions suspensives, les ajouter en a. b. etc.
C18: Conditions suspensives 1, 2, 3, 4. | D18: ='3. Hypothèses'!E38:E41 | E18: =Liste!K20 -> Autorisations administratives | G18: ARTICLE PRELIMINAIRE : BAIL SOUS CONDITION SUSPENSIVE 1. Condition suspensive et délais Le présent Bail est consenti et accepté par le Bailleur et le Preneur sous réserve de la réalisation de la condition suspensive suivante : - Obtention par le Preneur de l'ensemble des autorisations administratives pour la réalisation des travaux nécessaires à la bonne exploitation de son activité et à la mise en place dans les Locaux Loués de son concept, à savoir une Déclaration Préalable pour les modifications de façade, une demande d’Autorisation d’aménager un établissement recevant du public (ERP) ou toute autre autorisation administrative qui s’avérerait indispensable à l’ouverture et à l’exploitation des Locaux Loués au vu de la localisation spécifique de ces derniers. Le Preneur s’engage à justifier au Bailleur du dépôt de ces autorisations administratives au plus tard 1 (UN) mois après la signature des présentes. Ci-après la « Condition Suspensive » Chacune des Parties informera par tous moyens écrit l’autre partie de la réalisation de la condition suspensive qui lui incombe. En tout état de cause, la livraison des Locaux Loués au Preneur emportera levée de ladite condition suspensive sans autre formalité, chacune des Parties s’obligeant d’ores et déjà à respecter l’ensemble des clauses et conditions du présent Bail. Dans l'hypothèse où cette condition ne serait pas réalisée dans le délai indiqué ci-dessus, éventuellement prorogé, les obligations contractées par chacune des Parties au titre du présent Bail seront nulles et non avenues et les Parties reprendront, à ce titre, leur pleine et entière liberté sans indemnité de part et d’autre, les sommes versées par le Preneur lors de la signature du Bail lui seront remboursées. 2. Défaillance de la Condition Suspensive A défaut de réalisation de la Condition Suspensive dans le délai susvisé, les obligations contractées par chacune des Parties seront caduques, et les Parties reprendront leur pleine et entière liberté sans indemnité de part et d’autre, le Preneur ayant parfaitement connaissance de ce que le présent bail s’inscrit dans un contexte de libération desdits locaux laquelle n’est ni garantie et ni prévisible et ne pouvant, à ce titre, engager une quelconque action à l’encontre du Bailleur. Le Bailleur s’engageant à restituer au Preneur les sommes versées par le Preneur lors de la signature du Bail. | I18: Si plusieurs conditions suspensives | J18: ARTICLE PRELIMINAIRE : BAIL SOUS CONDITIONS SUSPENSIVES 1. Conditions suspensives et délais Le présent Bail est consenti et accepté par le Bailleur et le Preneur sous réserve de la réalisation des conditions suspensives suivantes : a. Obtention par le Preneur de l'ensemble des autorisations administratives pour la réalisation des travaux nécessaires à la bonne exploitation de son activité et à la mise en place dans les Locaux Loués de son concept, à savoir une Déclaration Préalable pour les modifications de façade, une demande d’Autorisation d’aménager un établissement recevant du public (ERP) ou toute autre autorisation administrative qui s’avérerait indispensable à l’ouverture et à l’exploitation des Locaux Loués au vu de la localisation spécifique de ces derniers. Le Preneur s’engage à justifier au Bailleur du dépôt de ces autorisations administratives au plus tard 1 (UN) mois après la signature des présentes. b. Ci-après les « Conditions Suspensives » Chacune des Parties informera par tous moyens écrit l’autre partie de la réalisation de la condition suspensive qui lui incombe. En tout état de cause, la livraison des Locaux Loués au Preneur emportera levée desdites conditions suspensives sans autre formalité, chacune des Parties s’obligeant d’ores et déjà à respecter l’ensemble des clauses et conditions du présent Bail. Dans l'hypothèse où ces conditions ne seraient pas réalisées dans le délai indiqué ci-dessus, éventuellement prorogé, les obligations contractées par chacune des Parties au titre du présent Bail seront nulles et non avenues et les Parties reprendront, à ce titre, leur pleine et entière liberté sans indemnité de part et d’autre, les sommes versées par le Preneur lors de la signature du Bail lui seront remboursées. 2. Défaillance des Conditions Suspensives A défaut de réalisation des Conditions Suspensives dans le délai susvisé, les obligations contractées par chacune des Parties seront caduques, et les Parties reprendront leur pleine et entière liberté sans indemnité de part et d’autre, le Preneur ayant parfaitement connaissance de ce que le présent bail s’inscrit dans un contexte de libération desdits locaux laquelle n’est ni garantie et ni prévisible et ne pouvant, à ce titre, engager une quelconque action à l’encontre du Bailleur. Le Bailleur s’engageant à restituer au Preneur les sommes versées par le Preneur lors de la signature du Bail.
C19: Conditions suspensives 1, 2, 3, 4. | D19: ='3. Hypothèses'!E38:E41 | E19: =Liste!K21 -> Extraction | G19: ARTICLE PRELIMINAIRE : BAIL SOUS CONDITION SUSPENSIVE 1. Condition suspensive et délais Le présent Bail est consenti et accepté par le Bailleur et le Preneur sous réserve de la réalisation de la condition suspensive suivante : - Obtention par le bailleur d’une autorisation de copropriété pour la réalisation de travaux d’installation d’un conduit d’extraction extérieur. Cette condition suspensive devra être levée au plus tard le [X] ; A ce titre, le preneur s’engage à communiquer au bailleur le dossier de travaux d’installation de la gaine d’extraction contenant l’ensemble des éléments nécessaires à la parfaite validation du projet (devis, visuels, rapport bureau d’étude, etc…) lui permettant de solliciter la convocation d’une assemblée générale. Le dossier susvisé devra être communiqué au bailleur au plus tard le [X]. Le Bailleur s’engage a voté favorablement pour l’adoption de ce projet. Ci-après la « Condition Suspensive » Chacune des Parties informera par tous moyens écrit l’autre partie de la réalisation de la condition suspensive qui lui incombe. En tout état de cause, la livraison des Locaux Loués au Preneur emportera levée de ladite condition suspensive sans autre formalité, chacune des Parties s’obligeant d’ores et déjà à respecter l’ensemble des clauses et conditions du présent Bail. Dans l'hypothèse où cette condition ne serait pas réalisée dans le délai indiqué ci-dessus, éventuellement prorogé, les obligations contractées par chacune des Parties au titre du présent Bail seront nulles et non avenues et les Parties reprendront, à ce titre, leur pleine et entière liberté sans indemnité de part et d’autre, les sommes versées par le Preneur lors de la signature du Bail lui seront remboursées. 2. Défaillance de la Condition Suspensive A défaut de réalisation de la Condition Suspensive dans le délai susvisé, les obligations contractées par chacune des Parties seront caduques, et les Parties reprendront leur pleine et entière liberté sans indemnité de part et d’autre, le Preneur ayant parfaitement connaissance de ce que le présent bail s’inscrit dans un contexte de libération desdits locaux laquelle n’est ni garantie et ni prévisible et ne pouvant, à ce titre, engager une quelconque action à l’encontre du Bailleur. Le Bailleur s’engageant à restituer au Preneur les sommes versées par le Preneur lors de la signature du Bail. | I19: Si plusieurs conditions suspensives | J19: ARTICLE PRELIMINAIRE : BAIL SOUS CONDITIONS SUSPENSIVES 1. Conditions suspensives et délais Le présent Bail est consenti et accepté par le Bailleur et le Preneur sous réserve de la réalisation des conditions suspensives suivantes : a. Obtention par le bailleur d’une autorisation de copropriété pour la réalisation de travaux d’installation d’un conduit d’extraction extérieur. Cette condition suspensive devra être levée au plus tard le [X] ; A ce titre, le preneur s’engage à communiquer au bailleur le dossier de travaux d’installation de la gaine d’extraction contenant l’ensemble des éléments nécessaires à la parfaite validation du projet (devis, visuels, rapport bureau d’étude, etc…) lui permettant de solliciter la convocation d’une assemblée générale. Le dossier susvisé devra être communiqué au bailleur au plus tard le [X]. Le Bailleur s’engage a voté favorablement pour l’adoption de ce projet. b. Ci-après les « Conditions Suspensives » Chacune des Parties informera par tous moyens écrit l’autre partie de la réalisation de la condition suspensive qui lui incombe. En tout état de cause, la livraison des Locaux Loués au Preneur emportera levée desdites conditions suspensives sans autre formalité, chacune des Parties s’obligeant d’ores et déjà à respecter l’ensemble des clauses et conditions du présent Bail. Dans l'hypothèse où ces conditions ne seraient pas réalisées dans le délai indiqué ci-dessus, éventuellement prorogé, les obligations contractées par chacune des Parties au titre du présent Bail seront nulles et non avenues et les Parties reprendront, à ce titre, leur pleine et entière liberté sans indemnité de part et d’autre, les sommes versées par le Preneur lors de la signature du Bail lui seront remboursées. 2. Défaillance des Conditions Suspensives A défaut de réalisation des Conditions Suspensives dans le délai susvisé, les obligations contractées par chacune des Parties seront caduques, et les Parties reprendront leur pleine et entière liberté sans indemnité de part et d’autre, le Preneur ayant parfaitement connaissance de ce que le présent bail s’inscrit dans un contexte de libération desdits locaux laquelle n’est ni garantie et ni prévisible et ne pouvant, à ce titre, engager une quelconque action à l’encontre du Bailleur. Le Bailleur s’engageant à restituer au Preneur les sommes versées par le Preneur lors de la signature du Bail.
C20: Conditions suspensives 1, 2, 3, 4. | D20: ='3. Hypothèses'!E38:E41 | E20: =Liste!K22 -> Libération des locaux | G20: ARTICLE PRELIMINAIRE : BAIL SOUS CONDITION SUSPENSIVE 1. Condition suspensive et délais Le présent Bail est consenti et accepté par le Bailleur et le Preneur sous réserve de la réalisation de la condition suspensive suivante : - Libération effective des Locaux Loués par l’actuel occupant, étant précisé que l’occupant a donné congé pour le [X]. Ci-après la « Condition Suspensive » Chacune des Parties informera par tous moyens écrit l’autre partie de la réalisation de la condition suspensive qui lui incombe. En tout état de cause, la livraison des Locaux Loués au Preneur emportera levée de ladite condition suspensive sans autre formalité, chacune des Parties s’obligeant d’ores et déjà à respecter l’ensemble des clauses et conditions du présent Bail. Dans l'hypothèse où cette condition ne serait pas réalisée dans le délai indiqué ci-dessus, éventuellement prorogé, les obligations contractées par chacune des Parties au titre du présent Bail seront nulles et non avenues et les Parties reprendront, à ce titre, leur pleine et entière liberté sans indemnité de part et d’autre, les sommes versées par le Preneur lors de la signature du Bail lui seront remboursées. 2. Défaillance de la Condition Suspensive A défaut de réalisation de la Condition Suspensive dans le délai susvisé, les obligations contractées par chacune des Parties seront caduques, et les Parties reprendront leur pleine et entière liberté sans indemnité de part et d’autre, le Preneur ayant parfaitement connaissance de ce que le présent bail s’inscrit dans un contexte de libération desdits locaux laquelle n’est ni garantie et ni prévisible et ne pouvant, à ce titre, engager une quelconque action à l’encontre du Bailleur. Le Bailleur s’engageant à restituer au Preneur les sommes versées par le Preneur lors de la signature du Bail. | I20: Si plusieurs conditions suspensives | J20: ARTICLE PRELIMINAIRE : BAIL SOUS CONDITIONS SUSPENSIVES 1. Conditions suspensives et délais Le présent Bail est consenti et accepté par le Bailleur et le Preneur sous réserve de la réalisation des conditions suspensives suivantes : a. Libération effective des Locaux Loués par l’actuel occupant, étant précisé que l’occupant a donné congé pour le [X] ; b. Ci-après les « Conditions Suspensives » Chacune des Parties informera par tous moyens écrit l’autre partie de la réalisation de la condition suspensive qui lui incombe. En tout état de cause, la livraison des Locaux Loués au Preneur emportera levée desdites conditions suspensives sans autre formalité, chacune des Parties s’obligeant d’ores et déjà à respecter l’ensemble des clauses et conditions du présent Bail. Dans l'hypothèse où ces conditions ne seraient pas réalisées dans le délai indiqué ci-dessus, éventuellement prorogé, les obligations contractées par chacune des Parties au titre du présent Bail seront nulles et non avenues et les Parties reprendront, à ce titre, leur pleine et entière liberté sans indemnité de part et d’autre, les sommes versées par le Preneur lors de la signature du Bail lui seront remboursées. 2. Défaillance des Conditions Suspensives A défaut de réalisation des Conditions Suspensives dans le délai susvisé, les obligations contractées par chacune des Parties seront caduques, et les Parties reprendront leur pleine et entière liberté sans indemnité de part et d’autre, le Preneur ayant parfaitement connaissance de ce que le présent bail s’inscrit dans un contexte de libération desdits locaux laquelle n’est ni garantie et ni prévisible et ne pouvant, à ce titre, engager une quelconque action à l’encontre du Bailleur. Le Bailleur s’engageant à restituer au Preneur les sommes versées par le Preneur lors de la signature du Bail.
C21: Conditions suspensives 1, 2, 3, 4. | D21: ='3. Hypothèses'!E38:E41 | E21: =Liste!K23 -> Autre | G21: ARTICLE PRELIMINAIRE : BAIL SOUS CONDITION SUSPENSIVE 1. Condition suspensive et délais Le présent Bail est consenti et accepté par le Bailleur et le Preneur sous réserve de la réalisation de la condition suspensive suivante : - Ci-après la « Condition Suspensive » Chacune des Parties informera par tous moyens écrit l’autre partie de la réalisation de la condition suspensive qui lui incombe. En tout état de cause, la livraison des Locaux Loués au Preneur emportera levée de ladite condition suspensive sans autre formalité, chacune des Parties s’obligeant d’ores et déjà à respecter l’ensemble des clauses et conditions du présent Bail. Dans l'hypothèse où cette condition ne serait pas réalisée dans le délai indiqué ci-dessus, éventuellement prorogé, les obligations contractées par chacune des Parties au titre du présent Bail seront nulles et non avenues et les Parties reprendront, à ce titre, leur pleine et entière liberté sans indemnité de part et d’autre, les sommes versées par le Preneur lors de la signature du Bail lui seront remboursées. 2. Défaillance de la Condition Suspensive A défaut de réalisation de la Condition Suspensive dans le délai susvisé, les obligations contractées par chacune des Parties seront caduques, et les Parties reprendront leur pleine et entière liberté sans indemnité de part et d’autre, le Preneur ayant parfaitement connaissance de ce que le présent bail s’inscrit dans un contexte de libération desdits locaux laquelle n’est ni garantie et ni prévisible et ne pouvant, à ce titre, engager une quelconque action à l’encontre du Bailleur. Le Bailleur s’engageant à restituer au Preneur les sommes versées par le Preneur lors de la signature du Bail. | I21: Si plusieurs conditions suspensives | J21: ARTICLE PRELIMINAIRE : BAIL SOUS CONDITIONS SUSPENSIVES 1. Conditions suspensives et délais Le présent Bail est consenti et accepté par le Bailleur et le Preneur sous réserve de la réalisation des conditions suspensives suivantes : a. b. Ci-après les « Conditions Suspensives » Chacune des Parties informera par tous moyens écrit l’autre partie de la réalisation de la condition suspensive qui lui incombe. En tout état de cause, la livraison des Locaux Loués au Preneur emportera levée desdites conditions suspensives sans autre formalité, chacune des Parties s’obligeant d’ores et déjà à respecter l’ensemble des clauses et conditions du présent Bail. Dans l'hypothèse où ces conditions ne seraient pas réalisées dans le délai indiqué ci-dessus, éventuellement prorogé, les obligations contractées par chacune des Parties au titre du présent Bail seront nulles et non avenues et les Parties reprendront, à ce titre, leur pleine et entière liberté sans indemnité de part et d’autre, les sommes versées par le Preneur lors de la signature du Bail lui seront remboursées. 2. Défaillance des Conditions Suspensives A défaut de réalisation des Conditions Suspensives dans le délai susvisé, les obligations contractées par chacune des Parties seront caduques, et les Parties reprendront leur pleine et entière liberté sans indemnité de part et d’autre, le Preneur ayant parfaitement connaissance de ce que le présent bail s’inscrit dans un contexte de libération desdits locaux laquelle n’est ni garantie et ni prévisible et ne pouvant, à ce titre, engager une quelconque action à l’encontre du Bailleur. Le Bailleur s’engageant à restituer au Preneur les sommes versées par le Preneur lors de la signature du Bail.
A22: Article 1 | B22: Désignation | C22: Ville ou arrondissement | D22: ='1. Données historiques'!E4 | G22: Dans un immeuble sis à ([Adresse Locaux Loués] (ci-après l’« Immeuble »), au rez-de-chaussée, un local commercial (ci-après les « Locaux Loués ») d’une surface d’environ [Surface totale] m² correspondant au(x) lot(s) de copropriété n°[.] et constitué de[.] et dont le plan est annexé au Bail.
A23: Article 1 | B23: Désignation | C23: Numéro et rue | D23: ='1. Données historiques'!D4
A24: Article 1 | B24: Désignation | C24: Surface totale | D24: ='1. Données historiques'!G4
A25: Article 2 | B25: Durée | C25: Durée du Bail | D25: ='3. Hypothèses'!E10 | F25: Si [Durée du Bail] = 9 | G25: Le présent Bail est conclu et accepté pour une durée de neuf (9) années entières et consécutives prenant effet le [Date de prise d'effet] pour se terminer le [Date de Prise d'effet + 9 ans]. Conformément à l’article L.145-4 du Code de commerce, le Preneur dispose de la faculté de donner congé à l'expiration de chacune des périodes triennales, au moins six mois à l'avance, par lettre recommandée avec demande d'avis de réception ou par acte extrajudiciaire. Si toutefois le Preneur entendait libérer les Locaux Loués avant l’un des termes contractuellement fixés, à quelque titre que ce soit, il sera tenu envers le Bailleur au jour de son départ, sous réserve de la rémunération d'autres chefs de préjudice, au paiement de l'intégralité des loyers, charges, taxes et impôts et autres accessoires dus au titre du Bail, jusqu’à la 1ère date utile de congé et ce, même si le Bailleur a procédé à la relocation des Locaux Loués. Le Bailleur aura également la faculté de donner congé, s’il entend invoquer le bénéfice des dispositions des articles L. 145-18, L. 145-21 et L. 145-24 du Code de Commerce, afin de construire ou reconstruire l’Immeuble existant, de le surélever ou d’exécuter des travaux prescrits ou autorisés dans le cadre d’une opération de restauration immobilière.
A26: Article 2 | B26: Durée | D26: ='3. Hypothèses'!E7 | E26: Date de prise d'effet | F26: Si "Durée du Bail" = 9
A27: Article 2 | B27: Durée | C27: Durée du Bail | D27: ='3. Hypothèses'!E10 | F27: Si [Durée du Bail] supérieur à 9 | G27: 2.1. – Le présent Bail est conclu et accepté pour une durée de [Durée du Bail] ([Durée du Bail en lettres]) années entières et consécutives prenant effet le [Date de prise d'effet] pour se terminer le [Date de prise d'effet + Durée du Bail]. La date d’effet du Bail correspondant au jour de la livraison des Locaux au Preneur. Le Preneur s’engage et accepte irrévocablement le présent Bail pour une durée ferme de [Durée ferme Bail] ([Durée ferme du Bail en lettres]) années pleines, entières et consécutives, commençant le [Date de prise d'effet] pour se terminer le [Date de prise d'effet + Durée ferme Bail] ; cet engagement constituant pour le Bailleur une condition déterminante du présent Bail, sans laquelle il n’aurait pas contracté. À l’issue de cette période de [Durée ferme Bail]([Durée ferme Bail en lettres]) années, le Preneur recouvrera sa faculté de résiliation triennale pour la [Si Durée ferme Bail = 6 ; "2ème" ; Si Durée ferme Bail = 9 ; "3ème"] période triennale à charge pour le Preneur de délivrer un congé soit par acte extrajudiciaire soit par lettre recommandée avec accusé de réception délivré au Bailleur au moins six (6) mois à l’avance. Si toutefois le Preneur entendait libérer les Locaux Loués avant l’un des termes contractuellement fixés, à quelque titre que ce soit, il sera tenu envers le Bailleur au jour de son départ, sous réserve de la rémunération d'autres chefs de préjudice, au paiement de l'intégralité des loyers, charges, taxes et impôts et autres accessoires dus au titre du Bail, jusqu’à la 1ère date utile de congé. Le Bailleur aura la faculté de donner congé, s’il entend invoquer le bénéfice des dispositions des articles L. 145-18, L. 145-21 et L. 145-24 du Code de Commerce, afin de construire ou reconstruire l’Immeuble existant, de le surélever ou d’exécuter des travaux prescrits ou autorisés dans le cadre d’une opération de restauration immobilière. 2.2. – Il est expressément convenu qu’à l’expiration du présent Bail et en cas de renouvellement éventuel dont, par hypothèse, les conditions statutaires seraient remplies par le Preneur, celui-ci interviendra pour une durée de [Durée du Bail] ([durée du Bail en lettres]) années et ce, par dérogation expresse à l’article L.145—12 du Code de commerce.
A28: Article 2 | B28: Durée | C28: Date de prise d'effet | D28: ='3. Hypothèses'!E7 | F28: Si "Durée du Bail" supérieur à 9
A29: Article 2 | B29: Durée | C29: Durée ferme Bail | D29: ='3. Hypothèses'!E11 | F29: Si "Durée du Bail" supérieur à 9
A30: Article 3 | B30: Destination | C30: Destination | D30: =Validation!B27 | G30: Le Preneur devra utiliser les Locaux Loués à usage exclusif de "[Destination]" et sous l’enseigne "[Enseigne] ".
D31: ='3. Hypothèses'!E45 | E31: Destination
D32: ='3. Hypothèses'!E46 | E32: Restauration sans extraction | F32: Si Restauration sans extraction = "Oui" | G32: "Le Preneur reconnaît être pleinement informé qu’au jour de la signature des présentes, il n’existe pas d’extraction dans les Locaux Loués ni de bac à graisse, par conséquent, il s’interdit dans le cadre des activités visées ci-dessus d’effectuer de la cuisson nécessitant une extraction ou une évacuation particulière des graisses. Si le Preneur souhaite toutefois installer une extraction et/ou un bac à graisse, et ce exclusivement après l’obtention de l’accord du Bailleur, il accepte expressément : - De faire son affaire personnelle de l’obtention de toutes les autorisations administratives nécessaires à l’installation desdits équipements et de prendre en charge tous les frais liés à l’obtention desdites autorisations, - De prendre à sa charge exclusive et sous sa responsabilité et à ses frais exclusifs tous les travaux concernant l’installation de ces équipements. En tout état de cause, si l’installation de ces équipements s’avérait techniquement impossible ou en cas de refus des autorisations nécessaires pour l’installation de ces équipements, les parties reconnaissent que la responsabilité du Bailleur ne pourra être engagée. Par ailleurs, le Bailleur se réserve le droit de demander la suppression sans délai des machines ou moteurs qui seraient installés par le Preneur, si leur fonctionnement venait à motiver des réclamations justifiées par des nuisances des locataires ou voisins. Il fera en sorte que le Bailleur ne puisse être inquiété, ni même recherché au sujet de ses équipements et de son activité."
A33: Article 5.3 | B33: Entretien et réparation | D33: ='3. Hypothèses'!E47 | E33: Option Accession | F33: Si [Option Accession] = "Immédiate" | G33: Les transformations et améliorations, tous travaux d'aménagement, d'embellissement, d'améliorations et d’installations réalisés par le Preneur dans les Locaux Loués deviendront propriété immédiate du Bailleur, sans indemnité de part et d’autre.
D34: ='3. Hypothèses'!E47 | E34: Option Accession | F34: Si [Option Accession] = "Fin du bail" | G34: Les transformations et améliorations, tous travaux d'aménagement, d'embellissement, d'améliorations et d’installations réalisés par le Preneur dans les Locaux Loués deviendront propriété du Bailleur, sans indemnité de part et d’autre, à la fin du présent bail.
D35: ='3. Hypothèses'!E47 | E35: Option Accession | F35: Si [Option Accession] = "Fin de jouissance" | G35: Les transformations et améliorations, tous travaux d'aménagement, d'embellissement, d'améliorations et d’installations réalisés par le Preneur dans les Locaux Loués deviendront propriété du Bailleur, sans indemnité de part et d’autre, en fin de jouissance c’est-à-dire au départ du Preneur.
A36: Article 7.1 | B36: Montant du loyer | D36: ='3. Hypothèses'!E8 | E36: Montant du loyer | G36: 7.1. – Montant du loyer Le loyer annuel est fixé, à compter de la prise d’effet du Bail, à la somme de [Montant du loyer] € HT HC ([Montant du loyer en lettres] EUROS HORS TAXES ET HORS CHARGES).
A37: Article 7.2 | B37: Actualisation et indexation | D37: ='3. Hypothèses'!E48 | E37: Actualisation | F37: Si [Actualisation] = "Oui" | G37: 7.2. – Actualisation et indexation du loyer 7.2.1. Actualisation Le loyer sera actualisé de plein droit et sans aucune formalité ni notification préalable en fonction de la variation de l’Indice national des Loyers Commerciaux (ILC) publié trimestriellement par l’INSEE. Cette actualisation interviendra à la date de prise d’effet du Bail, telle que définie à l’Article 2, en prenant pour référence le dernier indice connu à la date de signature du Bail ([.]) et en lui comparant l’indice publié à la date de prise d’effet du Bail. Le Preneur renonce expressément au bénéfice de discussion et à tous recours envers le Bailleur sur les conséquences résultant de l’actualisation du loyer tel que prévu au présent Article. 7.2.2. Indexation
D38: ='3. Hypothèses'!E48 | E38: Actualisation | F38: Si [Actualisation] ="Non" | G38: 7.2. – Indexation du loyer
A39: Article 7.3 | B39: Paiement des loyers | D39: ='3. Hypothèses'!E49 | E39: Paiement | F39: Si [Paiement] = "Prélèvement" | G39: 7.3.2. – Prélèvements sur compte bancaire Le Preneur autorise irrévocablement le Bailleur ou son mandataire à prélever sur le compte bancaire du Preneur, lors de leurs échéances, toutes les sommes qui lui seraient dues au titre du présent Bail. Le Bailleur prélèvera sur le compte bancaire du Preneur qui l’autorise dès à présent et irrévocablement, lors de leur échéance, les sommes qui lui seraient dues. Le Preneur remet au Bailleur le jour de la signature du Bail un mandat de prélèvement SEPA ou un exemplaire de l’imprimé de demande d’autorisation de prélèvement dûment complété, signé et accompagné d’un relevé d’identité bancaire. Le Preneur prendra toutes dispositions pour que son compte soit suffisamment approvisionné pour satisfaire aux prélèvements. À cet effet, leur montant lui sera notifié par le Bailleur au moins huit jours à l’avance. En cas de changement de domiciliation bancaire, le Preneur s’engage à remettre au Bailleur deux mois avant la plus proche échéance, un nouveau mandat de prélèvement SEPA ou un nouvel imprimé de demande d’autorisation de prélèvement dûment complété et signé.
D40: ='3. Hypothèses'!E49 | E40: Paiement | F40: Si [Paiement] = "Virement" | G40: 7.3.2. – Virements sur compte bancaire Le paiement des loyers en principal et accessoires et plus généralement de toutes sommes dues par le Preneur au Bailleur au titre du présent Bail sera effectué par virement bancaire. Il est toutefois expressément convenu entre les Parties qu’en cas de changement d’exploitant, le Bailleur aura la possibilité d’exiger du nouvel exploitant un paiement par prélèvement bancaire des sommes dues au titre du Bail
...

Sheet Liste données BAIL
A1: Données Primaire
A2: Nom | B2: Source
A3: Nom Preneur | B3: =Validation!B23
A4: Type Preneur | B4: =Validation!B24
A5: Siret Preneur | B5: =Validation!B25
A6: Société Bailleur | B6: ='1. Données historiques'!B4
A7: Ville ou arrondissement | B7: ='1. Données historiques'!E4
A8: Numéro et rue | B8: ='1. Données historiques'!D4
A9: Date LOI | B9: =Validation!B22
A10: Enseigne | B10: ='3. Hypothèses'!E45
A11: Statut Locaux loués | B11: ='1. Données historiques'!J4
A12: Durée Bail | B12: ='3. Hypothèses'!E10
A13: Durée ferme Bail | B13: ='3. Hypothèses'!E11
... A55: Période DG | B55: Si [Durée DG] = 3 ; "quart" ; Si [Durée DG] = 4 ; "tiers"; Si [Durée DG] = 6 ; "moitier";

Sheet Last Forecast
D1: Nav
L2: Début Trim | N2: =DATE(N5,MONTH(N3)-2,1) -> 44652 | O2: =DATE(O5,3*(O6-1)+1,1) -> 44743 | P2: =O3+1 -> 44835 | Q2: =P3+1 -> 44927 | R2: =Q3+1 -> 45017 | S2: =R3+1 -> 45108 | T2: =S3+1 -> 45200 | U2: =T3+1 -> 45292 | V2: =U3+1 -> 45383 | W2: =V3+1 -> 45474 | ... BD2: =BC3+1 -> 48488
L3: Fin Trim | N3: =O2-1 -> 44742 | O3: =DATE(YEAR(O2),MONTH(O2)+3,1)-1 -> 44834 | P3: =DATE(YEAR(P2),MONTH(P2)+3,1)-1 -> 44926 | Q3: =DATE(YEAR(Q2),MONTH(Q2)+3,1)-1 -> 45016 | R3: =DATE(YEAR(R2),MONTH(R2)+3,1)-1 -> 45107 | S3: =DATE(YEAR(S2),MONTH(S2)+3,1)-1 -> 45199 | T3: =DATE(YEAR(T2),MONTH(T2)+3,1)-1 -> 45291 | U3: =DATE(YEAR(U2),MONTH(U2)+3,1)-1 -> 45382 | V3: =DATE(YEAR(V2),MONTH(V2)+3,1)-1 -> 45473 | ... BD3: =DATE(YEAR(BD2),MONTH(BD2)+3,1)-1 -> 48579
L4: Nb jours | N4: =N3-N2+1 -> 91 | O4: =O3-O2+1 -> 92 | P4: =P3-P2+1 -> 92 | Q4: =Q3-Q2+1 -> 90 | R4: =R3-R2+1 -> 91 | S4: =S3-S2+1 -> 92 | T4: =T3-T2+1 -> 92 | U4: =U3-U2+1 -> 91 | ... BD4: =BD3-BD2+1 -> 92
L5: Année | N5: =IF(O6=1,O5-1,O5) -> 2022 | O5: 2022 | P5: =IF(P6=1,O5+1,O5) -> 2022 | Q5: =IF(Q6=1,P5+1,P5) -> 2023 | R5: =IF(R6=1,Q5+1,Q5) -> 2023 | S5: =IF(S6=1,R5+1,R5) -> 2023 | T5: =IF(T6=1,S5+1,S5) -> 2023 | U5: =IF(U6=1,T5+1,T5) -> 2024 | V5: =IF(V6=1,U5+1,U5) -> 2024 | W5: =IF(W6=1,V5+1,V5) -> 2024 | ... BD5: =IF(BD6=1,BC5+1,BC5) -> 2032
L6: Trimestre | N6: =IF(O6=1,4,O6-1) -> 2 | O6: 3 | P6: =IF(O6=4,1,O6+1) -> 4 | Q6: =IF(P6=4,1,P6+1) -> 1 | R6: =IF(Q6=4,1,Q6+1) -> 2 | S6: =IF(R6=4,1,R6+1) -> 3 | T6: =IF(S6=4,1,S6+1) -> 4 | U6: =IF(T6=4,1,T6+1) -> 1 | V6: =IF(U6=4,1,U6+1) -> 2 | W6: =IF(V6=4,1,V6+1) -> 3 | ... BD6: =IF(BC6=4,1,BC6+1) -> 4
C8: HSR | D8: Conso HSR
C9: =C8 -> HSR
C10: =C9 -> HSR | L10: % Palier | O10: =SUMIFS(O$260:O$10216,$L$260:$L$10216,$L10)/COUNTIFS($L$260:$L$10216,$L10) -> 0.14534884 | P10: =SUMIFS(P$260:P$10216,$L$260:$L$10216,$L10)/COUNTIFS($L$260:$L$10216,$L10) -> 0.14092518 | Q10: =SUMIFS(Q$260:Q$10216,$L$260:$L$10216,$L10)/COUNTIFS($L$260:$L$10216,$L10) -> 0.11162791 | R10: =SUMIFS(R$260:R$10216,$L$260:$L$10216,$L10)/COUNTIFS($L$260:$L$10216,$L10) -> 0.075389727 | S10: =SUMIFS(S$260:S$10216,$L$260:$L$10216,$L10)/COUNTIFS($L$260:$L$10216,$L10) -> 0.062815976 | T10: =SUMIFS(T$260:T$10216,$L$260:$L$10216,$L10)/COUNTIFS($L$260:$L$10216,$L10) -> 0.058139535 | U10: =SUMIFS(U$260:U$10216,$L$260:$L$10216,$L10)/COUNTIFS($L$260:$L$10216,$L10) -> 0.04625607 | V10: =SUMIFS(V$260:V$10216,$L$260:$L$10216,$L10)/COUNTIFS($L$260:$L$10216,$L10) -> 0.027855865 | ... BD10: =SUMIFS(BD$260:BD$10216,$L$260:$L$10216,$L10)/COUNTIFS($L$260:$L$10216,$L10) -> 0
C11: =C10 -> HSR | L11: % Loyer | O11: =SUMIFS(O$260:O$10216,$L$260:$L$10216,$L11)/COUNTIFS($L$260:$L$10216,$L11) -> 0.85452477 | P11: =SUMIFS(P$260:P$10216,$L$260:$L$10216,$L11)/COUNTIFS($L$260:$L$10216,$L11) -> 0.79657482 | Q11: =SUMIFS(Q$260:Q$10216,$L$260:$L$10216,$L11)/COUNTIFS($L$260:$L$10216,$L11) -> 0.78107235 | R11: =SUMIFS(R$260:R$10216,$L$260:$L$10216,$L11)/COUNTIFS($L$260:$L$10216,$L11) -> 0.7751725 | S11: =SUMIFS(S$260:S$10216,$L$260:$L$10216,$L11)/COUNTIFS($L$260:$L$10216,$L11) -> 0.75195905 | T11: =SUMIFS(T$260:T$10216,$L$260:$L$10216,$L11)/COUNTIFS($L$260:$L$10216,$L11) -> 0.74930485 | U11: =SUMIFS(U$260:U$10216,$L$260:$L$10216,$L11)/COUNTIFS($L$260:$L$10216,$L11) -> 0.73786098 | V11: =SUMIFS(V$260:V$10216,$L$260:$L$10216,$L11)/COUNTIFS($L$260:$L$10216,$L11) -> 0.73255814 | ... BD11: =SUMIFS(BD$260:BD$10216,$L$260:$L$10216,$L11)/COUNTIFS($L$260:$L$10216,$L11) -> 0.011627907
C12: =C11 -> HSR | L12: % Vacance loyer futur | O12: =SUMIFS(O$260:O$10216,$L$260:$L$10216,$L12)/COUNTIFS($L$260:$L$10216,$L12) -> 0.039749747 | P12: =SUMIFS(P$260:P$10216,$L$260:$L$10216,$L12)/COUNTIFS($L$260:$L$10216,$L12) -> 0.023319009 | Q12: =SUMIFS(Q$260:Q$10216,$L$260:$L$10216,$L12)/COUNTIFS($L$260:$L$10216,$L12) -> 0.011627907 | R12: =SUMIFS(R$260:R$10216,$L$260:$L$10216,$L12)/COUNTIFS($L$260:$L$10216,$L12) -> 0.011691797 | S12: =SUMIFS(S$260:S$10216,$L$260:$L$10216,$L12)/COUNTIFS($L$260:$L$10216,$L12) -> 0.0058139535 | T12: =SUMIFS(T$260:T$10216,$L$260:$L$10216,$L12)/COUNTIFS($L$260:$L$10216,$L12) -> 0.0058139535 | U12: =SUMIFS(U$260:U$10216,$L$260:$L$10216,$L12)/COUNTIFS($L$260:$L$10216,$L12) -> 0.0058139535 | V12: =SUMIFS(V$260:V$10216,$L$260:$L$10216,$L12)/COUNTIFS($L$260:$L$10216,$L12) -> 0.0058139535 | ... BD12: =SUMIFS(BD$260:BD$10216,$L$260:$L$10216,$L12)/COUNTIFS($L$260:$L$10216,$L12) -> 0
C13: =C12 -> HSR | L13: % Franchise loyer futur | O13: =SUMIFS(O$260:O$10216,$L$260:$L$10216,$L13)/COUNTIFS($L$260:$L$10216,$L13) -> 0.012702224 | P13: =SUMIFS(P$260:P$10216,$L$260:$L$10216,$L13)/COUNTIFS($L$260:$L$10216,$L13) -> 0.02148635 | Q13: =SUMIFS(Q$260:Q$10216,$L$260:$L$10216,$L13)/COUNTIFS($L$260:$L$10216,$L13) -> 0.010594315 | R13: =SUMIFS(R$260:R$10216,$L$260:$L$10216,$L13)/COUNTIFS($L$260:$L$10216,$L13) -> 0.0038972655 | S13: =SUMIFS(S$260:S$10216,$L$260:$L$10216,$L13)/COUNTIFS($L$260:$L$10216,$L13) -> 0.0079625885 | T13: =SUMIFS(T$260:T$10216,$L$260:$L$10216,$L13)/COUNTIFS($L$260:$L$10216,$L13) -> 0 | U13: =SUMIFS(U$260:U$10216,$L$260:$L$10216,$L13)/COUNTIFS($L$260:$L$10216,$L13) -> 0 | V13: =SUMIFS(V$260:V$10216,$L$260:$L$10216,$L13)/COUNTIFS($L$260:$L$10216,$L13) -> 0 | ... BD13: =SUMIFS(BD$260:BD$10216,$L$260:$L$10216,$L13)/COUNTIFS($L$260:$L$10216,$L13) -> 0
C14: =C13 -> HSR | L14: % Loyer futur | O14: =SUMIFS(O$260:O$10216,$L$260:$L$10216,$L14)/COUNTIFS($L$260:$L$10216,$L14) -> 0.10819009 | P14: =SUMIFS(P$260:P$10216,$L$260:$L$10216,$L14)/COUNTIFS($L$260:$L$10216,$L14) -> 0.19186047 | Q14: =SUMIFS(Q$260:Q$10216,$L$260:$L$10216,$L14)/COUNTIFS($L$260:$L$10216,$L14) -> 0.21899225 | R14: =SUMIFS(R$260:R$10216,$L$260:$L$10216,$L14)/COUNTIFS($L$260:$L$10216,$L14) -> 0.22489139 | S14: =SUMIFS(S$260:S$10216,$L$260:$L$10216,$L14)/COUNTIFS($L$260:$L$10216,$L14) -> 0.2539181 | T14: =SUMIFS(T$260:T$10216,$L$260:$L$10216,$L14)/COUNTIFS($L$260:$L$10216,$L14) -> 0.25663549 | U14: =SUMIFS(U$260:U$10216,$L$260:$L$10216,$L14)/COUNTIFS($L$260:$L$10216,$L14) -> 0.26801687 | V14: =SUMIFS(V$260:V$10216,$L$260:$L$10216,$L14)/COUNTIFS($L$260:$L$10216,$L14) -> 0.2733197 | ... BD14: =SUMIFS(BD$260:BD$10216,$L$260:$L$10216,$L14)/COUNTIFS($L$260:$L$10216,$L14) -> 0.98837209
C15: =C14 -> HSR
C16: =C15 -> HSR | L16: Indice loyer | M16: 1 | N16: 1 | O16: =SUMIFS(O$260:O$10216,$L$260:$L$10216,$L16)/COUNTIFS($L$260:$L$10216,$L16) -> 1.0085478 | P16: =SUMIFS(P$260:P$10216,$L$260:$L$10216,$L16)/COUNTIFS($L$260:$L$10216,$L16) -> 1.0119458 | Q16: =SUMIFS(Q$260:Q$10216,$L$260:$L$10216,$L16)/COUNTIFS($L$260:$L$10216,$L16) -> 1.0154645 | R16: =SUMIFS(R$260:R$10216,$L$260:$L$10216,$L16)/COUNTIFS($L$260:$L$10216,$L16) -> 1.0175441 | S16: =SUMIFS(S$260:S$10216,$L$260:$L$10216,$L16)/COUNTIFS($L$260:$L$10216,$L16) -> 1.0208217 | T16: =SUMIFS(T$260:T$10216,$L$260:$L$10216,$L16)/COUNTIFS($L$260:$L$10216,$L16) -> 1.0226163 | U16: =SUMIFS(U$260:U$10216,$L$260:$L$10216,$L16)/COUNTIFS($L$260:$L$10216,$L16) -> 1.0256211 | V16: =SUMIFS(V$260:V$10216,$L$260:$L$10216,$L16)/COUNTIFS($L$260:$L$10216,$L16) -> 1.0277196 | ... BD16: =SUMIFS(BD$260:BD$10216,$L$260:$L$10216,$L16)/COUNTIFS($L$260:$L$10216,$L16) -> 1.1184204
C17: =C16 -> HSR
C18: =C17 -> HSR | L18: Loyer bail | M18: =L18&"-"&C18 -> Loyer bail-HSR | O18: =SUMIFS(O$260:O$10216,$L$260:$L$10216,$L18) -> 3825536.6 | P18: =SUMIFS(P$260:P$10216,$L$260:$L$10216,$L18) -> 3888068.7 | Q18: =SUMIFS(Q$260:Q$10216,$L$260:$L$10216,$L18) -> 3981091.7 | R18: =SUMIFS(R$260:R$10216,$L$260:$L$10216,$L18) -> 4006343.8 | S18: =SUMIFS(S$260:S$10216,$L$260:$L$10216,$L18) -> 4113503.6 | T18: =SUMIFS(T$260:T$10216,$L$260:$L$10216,$L18) -> 4115017.6 | U18: =SUMIFS(U$260:U$10216,$L$260:$L$10216,$L18) -> 4115745.9 | V18: =SUMIFS(V$260:V$10216,$L$260:$L$10216,$L18) -> 4118535.4 | ... BD18: =SUMIFS(BD$260:BD$10216,$L$260:$L$10216,$L18) -> 4437787.7
C19: =C18 -> HSR | L19: Loyer indexé | M19: =L19&"-"&C19 -> Loyer indexé-HSR | O19: =SUMIFS(O$260:O$10216,$L$260:$L$10216,$L19) -> 4036122.3 | P19: =SUMIFS(P$260:P$10216,$L$260:$L$10216,$L19) -> 4100395.7 | Q19: =SUMIFS(Q$260:Q$10216,$L$260:$L$10216,$L19) -> 4200650.4 | R19: =SUMIFS(R$260:R$10216,$L$260:$L$10216,$L19) -> 4233610.1 | S19: =SUMIFS(S$260:S$10216,$L$260:$L$10216,$L19) -> 4302555.8 | T19: =SUMIFS(T$260:T$10216,$L$260:$L$10216,$L19) -> 4282241.1 | U19: =SUMIFS(U$260:U$10216,$L$260:$L$10216,$L19) -> 4298776.8 | V19: =SUMIFS(V$260:V$10216,$L$260:$L$10216,$L19) -> 4309690.9 | ... BD19: =SUMIFS(BD$260:BD$10216,$L$260:$L$10216,$L19) -> 4722122.9
C20: =C19 -> HSR | L20: Impact palier | M20: =L20&"-"&C20 -> Impact palier-HSR | O20: =SUMIFS(O$260:O$10216,$L$260:$L$10216,$L20) -> -148857.38 | P20: =SUMIFS(P$260:P$10216,$L$260:$L$10216,$L20) -> -169837.15 | Q20: =SUMIFS(Q$260:Q$10216,$L$260:$L$10216,$L20) -> -168325.38 | R20: =SUMIFS(R$260:R$10216,$L$260:$L$10216,$L20) -> -132599.47 | S20: =SUMIFS(S$260:S$10216,$L$260:$L$10216,$L20) -> -142001.8 | T20: =SUMIFS(T$260:T$10216,$L$260:$L$10216,$L20) -> -128512.67 | U20: =SUMIFS(U$260:U$10216,$L$260:$L$10216,$L20) -> -116074.6 | V20: =SUMIFS(V$260:V$10216,$L$260:$L$10216,$L20) -> -101655.29 | ... BD20: =SUMIFS(BD$260:BD$10216,$L$260:$L$10216,$L20) -> 0
C21: =C20 -> HSR | L21: Impact vacance future | M21: =L21&"-"&C21 -> Impact vacance future-HSR | O21: =SUMIFS(O$260:O$10216,$L$260:$L$10216,$L21) -> 0 | P21: =SUMIFS(P$260:P$10216,$L$260:$L$10216,$L21) -> 0 | Q21: =SUMIFS(Q$260:Q$10216,$L$260:$L$10216,$L21) -> 0 | R21: =SUMIFS(R$260:R$10216,$L$260:$L$10216,$L21) -> 0 | S21: =SUMIFS(S$260:S$10216,$L$260:$L$10216,$L21) -> 0 | T21: =SUMIFS(T$260:T$10216,$L$260:$L$10216,$L21) -> 0 | U21: =SUMIFS(U$260:U$10216,$L$260:$L$10216,$L21) -> 0 | V21: =SUMIFS(V$260:V$10216,$L$260:$L$10216,$L21) -> 0 | ... BD21: =SUMIFS(BD$260:BD$10216,$L$260:$L$10216,$L21) -> 0
C22: =C21 -> HSR | L22: Impact franchise | M22: =L22&"-"&C22 -> Impact franchise-HSR | O22: =SUMIFS(O$260:O$10216,$L$260:$L$10216,$L22) -> -75458.531 | P22: =SUMIFS(P$260:P$10216,$L$260:$L$10216,$L22) -> -97035.217 | Q22: =SUMIFS(Q$260:Q$10216,$L$260:$L$10216,$L22) -> -37227.778 | R22: =SUMIFS(R$260:R$10216,$L$260:$L$10216,$L22) -> -53655.473 | S22: =SUMIFS(S$260:S$10216,$L$260:$L$10216,$L22) -> -35951.087 | T22: =SUMIFS(T$260:T$10216,$L$260:$L$10216,$L22) -> 0 | U22: =SUMIFS(U$260:U$10216,$L$260:$L$10216,$L22) -> 0 | V22: =SUMIFS(V$260:V$10216,$L$260:$L$10216,$L22) -> 0 | ... BD22: =SUMIFS(BD$260:BD$10216,$L$260:$L$10216,$L22) -> 0
C23: =C22 -> HSR
C24: =C23 -> HSR | L24: Loyer | M24: =L24&"-"&C24 -> Loyer-HSR | O24: =SUMIFS(O$260:O$10216,$L$260:$L$10216,$L24) -> 3811806.4 | P24: =SUMIFS(P$260:P$10216,$L$260:$L$10216,$L24) -> 3833523.3 | Q24: =SUMIFS(Q$260:Q$10216,$L$260:$L$10216,$L24) -> 3995097.2 | R24: =SUMIFS(R$260:R$10216,$L$260:$L$10216,$L24) -> 4047355.1 | S24: =SUMIFS(S$260:S$10216,$L$260:$L$10216,$L24) -> 4124602.9 | T24: =SUMIFS(T$260:T$10216,$L$260:$L$10216,$L24) -> 4153728.4 | U24: =SUMIFS(U$260:U$10216,$L$260:$L$10216,$L24) -> 4182702.2 | V24: =SUMIFS(V$260:V$10216,$L$260:$L$10216,$L24) -> 4208035.6 | ... BD24: =SUMIFS(BD$260:BD$10216,$L$260:$L$10216,$L24) -> 4722122.9
C25: =C24 -> HSR
C26: =C25 -> HSR | L26: DE / DAB | M26: =L26&"-"&C26 -> DE / DAB-HSR | O26: =SUMIFS(O$260:O$10216,$L$260:$L$10216,$L26) -> 300000 | P26: =SUMIFS(P$260:P$10216,$L$260:$L$10216,$L26) -> 0 | Q26: =SUMIFS(Q$260:Q$10216,$L$260:$L$10216,$L26) -> 0 | R26: =SUMIFS(R$260:R$10216,$L$260:$L$10216,$L26) -> 0 | S26: =SUMIFS(S$260:S$10216,$L$260:$L$10216,$L26) -> 0 | T26: =SUMIFS(T$260:T$10216,$L$260:$L$10216,$L26) -> 0 | U26: =SUMIFS(U$260:U$10216,$L$260:$L$10216,$L26) -> 0 | V26: =SUMIFS(V$260:V$10216,$L$260:$L$10216,$L26) -> 0 | ... BD26: =SUMIFS(BD$260:BD$10216,$L$260:$L$10216,$L26) -> 0
C27: =C26 -> HSR | L27: IR | M27: =L27&"-"&C27 -> IR-HSR | O27: =SUMIFS(O$260:O$10216,$L$260:$L$10216,$L27) -> 1000000 | P27: =SUMIFS(P$260:P$10216,$L$260:$L$10216,$L27) -> 2125000 | Q27: =SUMIFS(Q$260:Q$10216,$L$260:$L$10216,$L27) -> 0 | R27: =SUMIFS(R$260:R$10216,$L$260:$L$10216,$L27) -> 1000000 | S27: =SUMIFS(S$260:S$10216,$L$260:$L$10216,$L27) -> 0 | T27: =SUMIFS(T$260:T$10216,$L$260:$L$10216,$L27) -> 0 | U27: =SUMIFS(U$260:U$10216,$L$260:$L$10216,$L27) -> 0 | V27: =SUMIFS(V$260:V$10216,$L$260:$L$10216,$L27) -> 0 | ... BD27: =SUMIFS(BD$260:BD$10216,$L$260:$L$10216,$L27) -> 0
C28: =C27 -> HSR | L28: FOC | M28: =L28&"-"&C28 -> FOC-HSR | O28: =SUMIFS(O$260:O$10216,$L$260:$L$10216,$L28) -> 0 | P28: =SUMIFS(P$260:P$10216,$L$260:$L$10216,$L28) -> 0 | Q28: =SUMIFS(Q$260:Q$10216,$L$260:$L$10216,$L28) -> 0 | R28: =SUMIFS(R$260:R$10216,$L$260:$L$10216,$L28) -> 300000 | S28: =SUMIFS(S$260:S$10216,$L$260:$L$10216,$L28) -> 0 | T28: =SUMIFS(T$260:T$10216,$L$260:$L$10216,$L28) -> 0 | U28: =SUMIFS(U$260:U$10216,$L$260:$L$10216,$L28) -> 0 | V28: =SUMIFS(V$260:V$10216,$L$260:$L$10216,$L28) -> 0 | ... BD28: =SUMIFS(BD$260:BD$10216,$L$260:$L$10216,$L28) -> 0
